Loading pytorch-gpu/py3/1.4.0
  Loading requirement: gcc/8.3.1 cuda/10.1.1 nccl/2.4.8-1-cuda
    cudnn/10.1-v7.5.1.10 openmpi/4.0.2-cuda
+ cd /linkhome/rech/genimt01/uba22to/NATL60/scripts/scripts_oi
+ python -u regrid_OI.py NATL
--------------------------------------------------------------------------
The library attempted to open the following supporting CUDA libraries,
but each of them failed.  CUDA-aware support is disabled.
libcuda.so.1: cannot open shared object file: No such file or directory
libcuda.dylib: cannot open shared object file: No such file or directory
/usr/lib64/libcuda.so.1: cannot open shared object file: No such file or directory
/usr/lib64/libcuda.dylib: cannot open shared object file: No such file or directory
If you are not interested in CUDA-aware support, then run with
--mca opal_warn_on_missing_libcuda 0 to suppress this message.  If you are interested
in CUDA-aware support, then try setting LD_LIBRARY_PATH to the location
of libcuda.so.1 to get passed this issue.
--------------------------------------------------------------------------
Exception ignored in: <function CachingFileManager.__del__ at 0x14a4e4056a70>
Traceback (most recent call last):
  File "/linkhome/rech/genimt01/uba22to/.local/lib/python3.7/site-packages/xarray/backends/file_manager.py", line 243, in __del__
  File "/linkhome/rech/genimt01/uba22to/.local/lib/python3.7/site-packages/xarray/backends/file_manager.py", line 217, in close
  File "/gpfslocalsup/pub/anaconda-py3/2019.03/envs/pytorch-gpu-1.4.0/lib/python3.7/contextlib.py", line 239, in helper
TypeError: 'NoneType' object is not callable
Exception ignored in: <function CachingFileManager.__del__ at 0x14a4e4056a70>
Traceback (most recent call last):
  File "/linkhome/rech/genimt01/uba22to/.local/lib/python3.7/site-packages/xarray/backends/file_manager.py", line 243, in __del__
  File "/linkhome/rech/genimt01/uba22to/.local/lib/python3.7/site-packages/xarray/backends/file_manager.py", line 217, in close
  File "/gpfslocalsup/pub/anaconda-py3/2019.03/envs/pytorch-gpu-1.4.0/lib/python3.7/contextlib.py", line 239, in helper
TypeError: 'NoneType' object is not callable
